Workbook
Name TASK: #REF!

Sheet KH Solar Plan
A2: FY 2024-25 | Khavda Solar Projects Monthly Commissioning Plan (MWac) | AH2: For Internal Purpose | AP2: 45747
A3: Priority | B3: Project | C3: SPV | D3: Plot No | E3: Plot No GP | F3: Category | G3: Category | H3: MMS Type | I3: Module Source | J3: Module Wp | K3: Capacity (MWac) | L3: OL | M3: Capacity (MWdc) | O3: PSS No. | P3: PSS Charging Date | Q3: SCOD | R3: Commissioning as per Growth Plan | S3: Plot Head | T3: Commissioning as per Growth Plan (R5 - 08-Feb-25) | U3: Capex BOQ Release Date | V3: LTA Phase | W3: Expected LTA Operationalization | X3: Plant Code | Y3: SUPPLY Plant Code | Z3: SERVICE Plant Code | AA3: Commissioning as per Growth Plan | AB3: Charging Start | AC3: Charging Finish | AE3: Capex NFA Status | AF3: 45748 | AG3: 45778 | AH3: 45809 | AI3: 45839 | AJ3: 45870 | AK3: 45901 | AL3: 45931 | AM3: 45962 | AN3: 45992 | AO3: 46023 | AP3: 46054 | AQ3: 46082 | AR3: Total (MW)
A4: 10 | B4: AGEL Merchant | C4: ARE56L | D4: S-08 | F4: Merchant | G4: Merchant | H4: HSAT | K4: 400 | L4: 1.37 | M4: 548 | O4: PSS-09 | P4: Charged | S4: Arvind Kulshrestha | T4: 45717 | AF4: 150 | AG4: 100 | AR4: =SUM(AF4:AQ4) -> 250
A5: 13 | B5: AGEL Merchant | C5: ARE56L | D5: A-02 | F5: Merchant | G5: Merchant | H5: HSAT | K5: 225 | L5: 1.37 | M5: 308.25 | O5: PSS-04 | P5: Charged | S5: Akhil Agarwal | T5: 45717 | AF5: 50 | AR5: =SUM(AF5:AQ5) -> 50
A6: 11 | B6: MLP AP New | C6: ARE57L | D6: A-11 | F6: PPA | G6: PPA | H6: HSAT | K6: 500 | L6: 1.36 | M6: 680 | O6: PSS-13 | P6: Charged | S6: Salim Beg | T6: 45717 | AF6: 187.5 | AR6: =SUM(AF6:AQ6) -> 187.5
A7: 12 | B7: MLP AP New | C7: ARE57L | D7: A-12 | F7: PPA | G7: PPA | H7: HSAT | K7: 350 | L7: 1.35 | M7: =L7*K7 -> 472.5 | O7: PSS-13 | P7: Charged | S7: Bikash Kumar | T7: 45717 | AH7: 100 | AI7: 250 | AR7: =SUM(AF7:AQ7) -> 350
A8: 14 | B8: SECI H-3 | C8: AHEJ5L | D8: A-13 | F8: PPA | G8: PPA | H8: FT | K8: 570 | L8: 1.4 | M8: 798 | O8: PSS-05 | P8: Charged | S8: Syed Ali | T8: 45717 | AF8: 295 | AH8: 275 | AR8: =SUM(AF8:AQ8) -> 570
A9: 15 | B9: AGEL Merchant | C9: ARE45L | D9: A-14 | F9: Merchant | G9: Merchant | H9: HSAT | K9: 250 | L9: 1.37 | M9: 342.5 | O9: PSS-05 | P9: Charged | S9: Syed Ali | T9: 45717 | AF9: 150 | AG9: 100 | AR9: =SUM(AF9:AQ9) -> 250
A10: 16 | B10: MLP T3 AP | C10: ARE56L | D10: S-06 | F10: PPA | G10: PPA | H10: HSAT | K10: 500 | L10: 1.37 | M10: 685 | O10: PSS-10 | P10: Charged | S10: Ramesh Suthar | T10: 45717 | AF10: 100 | AH10: 100 | AI10: 300 | AR10: =SUM(AF10:AQ10) -> 500
A11: Monthwise FY 24-25 Projects (A) | K11: 4045 | M11: =SUM(M4:M10) -> 3834.25 | AF11: =SUM(AF4:AF10) -> 932.5 | AG11: =SUM(AG4:AG10) -> 200 | AH11: =SUM(AH4:AH10) -> 475 | AI11: =SUM(AI4:AI10) -> 550 | AR11: =SUM(AF11:AQ11) -> 2157.5
AF12: 600 | AG12: 200 | AH12: 325 | AI12: 550
P13: Category | R13: Category | T13: =U13 -> Capacity (MWac) | U13: Capacity (MWac) | AF13: 45748 | AG13: 45778 | AH13: 45809 | AI13: 45839 | AJ13: 45870 | AK13: 45901 | AL13: 45931 | AM13: 45962 | AN13: 45992 | AO13: 46023 | AP13: 46054 | AQ13: 46082
P14: Merchant | R14: Merchant | T14: =SUM(AF14:AQ14) -> 550 | U14: =SUMIF($G$23:$G$43,$R14,K$23:K$43) -> 1227 | AF14: =SUMIF($G$4:$G$10,$R14,AF$4:AF$10) -> 350 | AG14: =SUMIF($G$4:$G$10,$R14,AG$4:AG$10) -> 200 | AH14: =SUMIF($G$4:$G$10,$R14,AH$4:AH$10) -> 0 | AI14: =SUMIF($G$4:$G$10,$R14,AI$4:AI$10) -> 0 | AJ14: =SUMIF($G$4:$G$10,$R14,AJ$4:AJ$10) -> 0 | AK14: =SUMIF($G$4:$G$10,$R14,AK$4:AK$10) -> 0 | AL14: =SUMIF($G$4:$G$10,$R14,AL$4:AL$10) -> 0 | AM14: =SUMIF($G$4:$G$10,$R14,AM$4:AM$10) -> 0 | ... AQ14: =SUMIF($G$4:$G$10,$R14,AQ$4:AQ$10) -> 0
P15: PPA | R15: PPA | T15: =SUM(AF15:AQ15) -> 1607.5 | U15: =SUMIF($G$23:$G$43,$R15,K$23:K$43) -> 1650 | AF15: =SUMIF($G$4:$G$10,$R15,AF$4:AF$10) -> 582.5 | AG15: =SUMIF($G$4:$G$10,$R15,AG$4:AG$10) -> 0 | AH15: =SUMIF($G$4:$G$10,$R15,AH$4:AH$10) -> 475 | AI15: =SUMIF($G$4:$G$10,$R15,AI$4:AI$10) -> 550 | AJ15: =SUMIF($G$4:$G$10,$R15,AJ$4:AJ$10) -> 0 | AK15: =SUMIF($G$4:$G$10,$R15,AK$4:AK$10) -> 0 | AL15: =SUMIF($G$4:$G$10,$R15,AL$4:AL$10) -> 0 | AM15: =SUMIF($G$4:$G$10,$R15,AM$4:AM$10) -> 0 | ... AQ15: =SUMIF($G$4:$G$10,$R15,AQ$4:AQ$10) -> 0
P16: Group | R16: Group | T16: =SUM(AF16:AQ16) -> 0 | U16: =SUMIF($G$23:$G$43,$R16,K$23:K$43) -> 150 | AF16: =SUMIF($G$4:$G$10,$R16,AF$4:AF$10) -> 0 | AG16: =SUMIF($G$4:$G$10,$R16,AG$4:AG$10) -> 0 | AH16: =SUMIF($G$4:$G$10,$R16,AH$4:AH$10) -> 0 | AI16: =SUMIF($G$4:$G$10,$R16,AI$4:AI$10) -> 0 | AJ16: =SUMIF($G$4:$G$10,$R16,AJ$4:AJ$10) -> 0 | AK16: =SUMIF($G$4:$G$10,$R16,AK$4:AK$10) -> 0 | AL16: =SUMIF($G$4:$G$10,$R16,AL$4:AL$10) -> 0 | AM16: =SUMIF($G$4:$G$10,$R16,AM$4:AM$10) -> 0 | ... AQ16: =SUMIF($G$4:$G$10,$R16,AQ$4:AQ$10) -> 0
P17: EPC | R17: EPC | T17: =SUM(AF17:AQ17) -> 0 | U17: =SUMIF($G$23:$G$43,$R17,K$23:K$43) -> 0 | AF17: =SUMIF($G$4:$G$10,$R17,AF$4:AF$10) -> 0 | AG17: =SUMIF($G$4:$G$10,$R17,AG$4:AG$10) -> 0 | AH17: =SUMIF($G$4:$G$10,$R17,AH$4:AH$10) -> 0 | AI17: =SUMIF($G$4:$G$10,$R17,AI$4:AI$10) -> 0 | AJ17: =SUMIF($G$4:$G$10,$R17,AJ$4:AJ$10) -> 0 | AK17: =SUMIF($G$4:$G$10,$R17,AK$4:AK$10) -> 0 | AL17: =SUMIF($G$4:$G$10,$R17,AL$4:AL$10) -> 0 | AM17: =SUMIF($G$4:$G$10,$R17,AM$4:AM$10) -> 0 | ... AQ17: =SUMIF($G$4:$G$10,$R17,AQ$4:AQ$10) -> 0
P18: Total | R18: Total | T18: =SUM(AF18:AQ18) -> 2157.5 | U18: =SUM(U14:U17) -> 3027 | V18: =SUM(V14:V17) -> 0 | W18: =SUM(W14:W17) -> 0 | X18: =SUM(X14:X17) -> 0 | Y18: =SUM(Y14:Y17) -> 0 | Z18: =SUM(Z14:Z17) -> 0 | AA18: =SUM(AA14:AA17) -> 0 | AB18: =SUM(AB14:AB17) -> 0 | ... AQ18: =SUM(AQ14:AQ17) -> 0
AF20: 1145 | AG20: 550 | AH20: 375
A21: FY 2025-26 | Khavda Solar Projects Monthly Commissioning Plan (MWac) | AH21: In May-25 & Jun-25 @1.15 OL & balance 1.37 OL by Jul to Sep-25
A22: Priority | B22: Project | C22: SPV | D22: Plot No | E22: Plot No GP | F22: Category | G22: Category | H22: MMS Type | I22: Module Source | J22: Module Wp | K22: Capacity (MWac) | L22: OL | M22: Capacity (MWdc) | N22: IDT (No.s) | O22: PSS No. | P22: PSS Charging Date | Q22: SCOD | R22: Commissioning as per Growth Plan | S22: Plot Head | T22: Commissioning as per Growth Plan (R5 - 08-Feb-25) | U22: Capex BOQ Release Date | V22: LTA Phase | W22: Expected LTA Operationalization | X22: Plant Code | Y22: SUPPLY Plant Code | Z22: SERVICE Plant Code | AA22: Commissioning as per Growth Plan | AB22: Charging Start | AC22: Charging Finish | AE22: Capex NFA Status | AF22: 45748 | AG22: 45778 | AH22: 45809 | AI22: 45839 | AJ22: 45870 | AK22: 45901 | AL22: 45931 | AM22: 45962 | AN22: 45992 | AO22: 46023 | AP22: 46054 | AQ22: 46082
A23: P-01 | B23: Google Hybrid | C23: ARE3L | D23: A-6 | E23: A18 | F23: Merchant-Google | G23: Merchant | H23: HSAT | I23: ALMM | J23: 580 | K23: =SUM(AF23:AQ23) -> 25 | L23: 1.35 | M23: =L23*K23 -> 33.75 | N23: 2 | O23: PSS-08 | P23: 45851 | Q23: - | R23: 45838 | S23: Trilochan Saggu | T23: 45838 | U23: 45615 | V23: Phase - II | W23: 45747 | AH23: 25 | AR23: =SUM(AF23:AQ23) -> 25
A24: P-02 | B24: AGEL Merchant | C24: ASEJ6PL | D24: A-6 | E24: A18, S9 | F24: Merchant-Hybrid | G24: Merchant | H24: HSAT | I24: ALMM | J24: 580 | K24: =SUM(AF24:AQ24) -> 35 | L24: 1.35 | M24: =L24*K24 -> 47.25 | N24: 3 | O24: PSS-08 | P24: =P23 -> 45851 | Q24: - | R24: 45838 | S24: Trilochan Saggu | T24: 45838 | U24: 45615 | V24: Phase - II | W24: 45747 | AH24: 35 | AR24: =SUM(AF24:AQ24) -> 35
A25: P-03 | B25: AGEL Hybrid Merchant | C25: ARE48L | D25: S-8 | E25: S7, S8 | F25: Merchant-Hybrid | G25: Merchant | H25: HSAT | I25: ALMM | J25: 580 | K25: =SUM(AF25:AQ25) -> 100 | L25: 1.35 | M25: =L25*K25 -> 135 | N25: 8 | O25: PSS-09 | P25: Charged | Q25: - | R25: 45838 | S25: Arvind / Dhritiman | T25: 45838 | U25: 45615 | V25: Phase - III | W25: 46022 | AO25: 100 | AR25: =SUM(AF25:AQ25) -> 100
A26: P-04 | B26: AGEL Merchant | C26: AHEJ5L | D26: A-15a | E26: A15 | F26: Merchant | G26: Merchant | H26: HSAT | I26: ALMM | J26: 580 | K26: =SUM(AF26:AQ26) -> 150 | L26: 1.35 | M26: =L26*K26 -> 202.5 | N26: 12 | O26: PSS-08 | P26: =P24 -> 45851 | Q26: - | R26: 45838 | S26: Atul Kumar Kothari | T26: 45838 | U26: 45615 | V26: Phase - II | W26: 45747 | AM26: 50 | AO26: 100 | AR26: =SUM(AF26:AQ26) -> 150
A27: P-05a | B27: AGEL Hybrid Merchant | C27: AGE26BL | D27: S-5 | E27: S5, S6 | F27: Merchant-Hybrid | G27: Merchant | H27: HSAT | I27: ALMM | J27: 580 | K27: =SUM(AF27:AQ27) -> 142 | L27: 1.35 | M27: =L27*K27 -> 191.7 | N27: 24 | O27: PSS-10 | P27: =P10 -> Charged | Q27: - | R27: 46022 | S27: P. Raja | T27: 45838 | U27: 45622 | V27: Phase - III | W27: 46022 | AG27: 100 | AH27: 42 | AR27: =SUM(AF27:AQ27) -> 142
A28: P-05b | B28: AGEL Merchant | C28: AGE26BL | D28: S-5 | E28: S5, S6 | F28: Merchant-Hybrid | G28: Merchant | H28: HSAT | I28: ALMM | J28: 580 | K28: =SUM(AF28:AQ28) -> 150 | L28: 1.35 | M28: =L28*K28 -> 202.5 | N28: 24 | O28: PSS-10 | P28: =+P27 -> Charged | Q28: - | R28: 46022 | S28: P. Raja | T28: 45838 | U28: 45622 | V28: Phase - III | W28: 46022 | AH28: 150 | AR28: =SUM(AF28:AQ28) -> 150
A29: P-06 | B29: AGEL Merchant | C29: AGE24L | D29: S-5 | E29: S5, S6 | F29: Merchant | G29: Merchant | H29: HSAT | I29: ALMM | J29: 580 | K29: =SUM(AF29:AQ29) -> 150 | L29: 1.35 | M29: =L29*K29 -> 202.5 | N29: 12 | O29: PSS-10 | P29: =P27 -> Charged | Q29: - | R29: 46022 | S29: P. Raja | T29: 45838 | U29: 45622 | V29: Phase - III | W29: 46022 | AG29: 50 | AH29: 100 | AR29: =SUM(AF29:AQ29) -> 150
A30: P-07 | B30: AGEL Merchant | C30: AGE24L | D30: A-14 | E30: A13, A14, A17 | F30: Merchant | G30: Merchant | H30: HSAT | I30: ALMM | J30: 580 | K30: =SUM(AF30:AQ30) -> 150 | L30: 1.35 | M30: =L30*K30 -> 202.5 | N30: 12 | O30: PSS-05 | P30: =P9 -> Charged | Q30: - | S30: Syed Ali | T30: 45838 | AM30: 150 | AR30: =SUM(AF30:AQ30) -> 150
A31: P-08 | B31: Cement - Hybrid | C31: ACL | D31: A-1 | E31: A1, A2 | F31: Cement - Hybrid | G31: Group | H31: FT | I31: ALMM | J31: 580 | K31: =SUM(AF31:AQ31) -> 125 | L31: 1.36 | M31: =L31*K31 -> 170 | N31: 10 | O31: PSS-04 | P31: =P5 -> Charged | Q31: - | R31: 45838 | S31: Rupesh Kumar | T31: 45838 | U31: 45615 | V31: Phase - II | W31: 45747 | AH31: 125 | AR31: =SUM(AF31:AQ31) -> 125
A32: P-14 | B32: MLP T3 AP | C32: AGE25CL | D32: A-6 | E32: A6 | F32: PPA | G32: PPA | H32: HSAT | I32: China | K32: =SUM(AF32:AQ32) -> 75 | L32: 1.35 | M32: =L32*K32 -> 101.25 | N32: 6 | O32: PSS-08 | P32: =P24 -> 45851 | Q32: 45966 | T32: 45931 | AM32: 75 | AR32: =SUM(AF32:AQ32) -> 75
A33: P-09 | B33: MLP T1 J&K | C33: AGE26AL | D33: A-16 | E33: A16 | F33: PPA | G33: PPA | H33: FT | I33: SEA | K33: =SUM(AF33:AQ33) -> 50 | L33: 1.36 | M33: =L33*K33 -> 68 | N33: 4 | O33: PSS-06 | P33: 45976 | Q33: 45734 | R33: 45930 | T33: 45930 | U33: 45608 | V33: Phase - I | W33: 45309 | AK33: 50 | AR33: =SUM(AF33:AQ33) -> 50
A34: P-10 | B34: MLP T1 CG | C34: AGE26AL | D34: A-16 | E34: A16 | F34: PPA | G34: PPA | H34: FT | I34: SEA | K34: =SUM(AF34:AQ34) -> 200 | L34: 1.36 | M34: =L34*K34 -> 272 | N34: 16 | O34: PSS-06 | P34: =P33 -> 45976 | Q34: 45734 | R34: 45930 | T34: 45930 | U34: 45608 | V34: Phase - I | W34: 45309 | AL34: 200 | AR34: =SUM(AF34:AQ34) -> 200
A35: P-11 | B35: MLP T1 TN | C35: AGE26AL | D35: A-16 | E35: A16 | F35: PPA | G35: PPA | H35: FT | I35: SEA | K35: =SUM(AF35:AQ35) -> 167 | L35: 1.36 | M35: =L35*K35 -> 227.12 | N35: 14 | O35: PSS-06 | P35: =P34 -> 45976 | Q35: 45734 | R35: 45930 | T35: 45930 | U35: 45608 | V35: Phase - I | W35: 45309 | AL35: 167 | AR35: =SUM(AF35:AQ35) -> 167
A36: P-12 | B36: MLP T1 OR | C36: AGE26AL | D36: A-16 | E36: A16 | F36: PPA | G36: PPA | H36: FT | I36: SEA | K36: =SUM(AF36:AQ36) -> 333 | L36: 1.36 | M36: =L36*K36 -> 452.88 | N36: 27 | O36: PSS-06 | P36: 46014 | Q36: 45734 | R36: 45930 | T36: 45930 | U36: 45608 | V36: Phase - I | W36: 45309 | AK36: 333 | AR36: =SUM(AF36:AQ36) -> 333
A37: P-13 | B37: MLP T1 TR | C37: AGE26AL | D37: A10a | E37: A9, A10 | F37: PPA | G37: PPA | H37: FT | I37: SEA | K37: =SUM(AF37:AQ37) -> 50 | L37: 1.36 | M37: =L37*K37 -> 68 | N37: 4 | O37: PSS-03 | P37: Charged | Q37: 45561 | R37: 45838 | T37: 45930 | U37: 45608 | V37: Phase - II | W37: 45747 | AK37: 50 | AR37: =SUM(AF37:AQ37) -> 50
A38: P-15 | B38: MLP T3 AP | C38: AGE25CL | D38: A-6 | E38: A6 | F38: PPA | G38: PPA | H38: FT | I38: China | K38: =SUM(AF38:AQ38) -> 425 | L38: 1.36 | M38: =L38*K38 -> 578 | N38: 34 | O38: PSS-08 | P38: =P19 -> 0 | AN38: 425 | AR38: =SUM(AF38:AQ38) -> 425
A39: P-16 | B39: AGEL Hybrid Merchant | C39: AHEJ5L | D39: S-4 | E39: Merchant | F39: Merchant | G39: Merchant | H39: HSAT | K39: 300 | L39: 1.35 | M39: =L39*K39 -> 405 | N39: PSS-11 | AN39: 100 | AO39: 100 | AP39: 100 | AR39: =SUM(AF39:AQ39) -> 300
A40: P-17 | B40: =B14 -> 0 | C40: =C14 -> 0 | D40: =D14 -> 0 | E40: PPA | F40: PPA | G40: PPA | H40: HSAT | K40: 350 | L40: 1.35 | M40: =L40*K40 -> 472.5 | N40: =N14 -> 0 | AO40: 150 | AP40: 200 | AR40: =SUM(AF40:AQ40) -> 350
A41: P-18a | B41: KCTL | C41: KCTL | D41: A-15a | E41: Group | F41: Copper | G41: Group | H41: HSAT | K41: 12.5 | L41: 1.35 | M41: =L41*K41 -> 16.875 | N41: PSS-08 | AR41: =SUM(AF41:AQ41) -> 0
A42: P-18b | B42: MCIPL | C42: MCIPL | D42: A-15a | E42: Group | F42: Copper | G42: Group | H42: HSAT | K42: 12.5 | L42: 1.35 | M42: =L42*K42 -> 16.875 | N42: PSS-08 | AR42: =SUM(AF42:AQ42) -> 0
...

Sheet KH Solar Rephase
A2: FY 2024-25 | Khavda Solar Projects Monthly Commissioning Plan (MWac) | AI2: For Internal Purpose | AO2: 45840
A3: Priority | B3: Project | C3: SPV | D3: Plot No | E3: Plot No GP | F3: Category | G3: Category | H3: MMS Type | I3: Module Source | J3: Module Wp | K3: Capacity (MWac) | L3: OL | M3: Capacity (MWdc) | N3: PSS No. | O3: PSS Charging Date | P3: SCOD | Q3: Commissioning as per Growth Plan | R3: Plot Head | S3: Commissioning as per Growth Plan (R5 - 08-Feb-25) | T3: Capex BOQ Release Date | U3: LTA Phase | V3: Expected LTA Operationalization | W3: Plant Code | X3: SUPPLY Plant Code | Y3: SERVICE Plant Code | Z3: Commissioning as per Growth Plan | AA3: Charging Start | AB3: Charging Finish | AD3: Capex NFA Status | AE3: 45748 | AF3: 45778 | AG3: 45809 | AH3: 45839 | AI3: 45870 | AJ3: 45901 | AK3: 45931 | AL3: 45962 | AM3: 45992 | AN3: 46023 | AO3: 46054 | AP3: 46082 | AQ3: Total (MW)
A4: 10 | B4: AGEL Merchant | C4: ARE56L | D4: S-08 | F4: Merchant | G4: Merchant | H4: HSAT | K4: 250 | L4: 1.37 | M4: 548 | N4: PSS-09 | O4: Charged | R4: Arvind Kulshrestha | S4: 45717 | AF4: 75 | AG4: 50 | AH4: 50 | AI4: 75 | AJ4: 0 | AK4: 0 | AQ4: =SUM(AE4:AP4) -> 250
A5: 11 | B5: MLP AP New | C5: ARE57L | D5: A-11 | F5: PPA | G5: PPA | H5: HSAT | K5: 50 | L5: 1.36 | M5: 680 | N5: PSS-13 | O5: Charged | R5: Salim Beg | S5: 45717 | AF5: 50 | AG5: 0 | AH5: 0 | AI5: 0 | AJ5: 0 | AK5: 0 | AQ5: =SUM(AE5:AP5) -> 50
A6: 12 | B6: MLP AP New | C6: ARE57L | D6: A-12 | F6: PPA | G6: PPA | H6: HSAT | K6: 187.5 | L6: 1.35 | M6: =L6*K6 -> 253.125 | N6: PSS-13 | O6: Charged | R6: Bikash Kumar | S6: 45717 | AE6: 75 | AF6: 112.5 | AG6: 0 | AK6: 0 | AQ6: =SUM(AE6:AP6) -> 187.5
A7: 13 | B7: AGEL Merchant | C7: ARE56L | D7: A-02 | F7: Merchant | G7: Merchant | H7: HSAT | K7: 350 | L7: 1.37 | M7: 308.25 | N7: PSS-04 | O7: Charged | R7: Akhil Agarwal | S7: 45717 | AF7: 50 | AG7: 175 | AH7: 0 | AI7: 75 | AJ7: 50 | AK7: 0 | AQ7: =SUM(AE7:AP7) -> 350
A8: 14 | B8: SECI H-3 | C8: AHEJ5L | D8: A-13 | F8: PPA | G8: PPA | H8: FT | K8: 570 | L8: 1.4 | M8: 798 | N8: PSS-05 | O8: Charged | R8: Syed Ali | S8: 45717 | AE8: 145 | AG8: 150 | AH8: 75 | AJ8: 50 | AK8: 50 | AL8: 100 | AQ8: =SUM(AE8:AP8) -> 570
A9: 15 | B9: AGEL Merchant | C9: ARE45L | D9: A-14 | F9: Merchant | G9: Merchant | H9: HSAT | K9: 250 | L9: 1.37 | M9: 342.5 | N9: PSS-05 | O9: Charged | R9: Syed Ali | S9: 45717 | AE9: 50 | AG9: 125 | AI9: 75 | AJ9: 0 | AK9: 0 | AQ9: =SUM(AE9:AP9) -> 250
A10: 16 | B10: MLP T3 AP | C10: ARE56L | D10: S-06 | F10: PPA | G10: PPA | H10: HSAT | K10: 500 | L10: 1.37 | M10: 685 | N10: PSS-10 | O10: Charged | R10: Ramesh Suthar | S10: 45717 | AE10: 100 | AG10: 137.5 | AH10: 112.5 | AJ10: 50 | AK10: 50 | AL10: 50 | AQ10: =SUM(AE10:AP10) -> 500
A11: Monthwise FY 24-25 Projects (A) | K11: 4045 | M11: =SUM(M4:M10) -> 3614.875 | AE11: =SUM(AE4:AE10) -> 370 | AF11: =SUM(AF4:AF10) -> 287.5 | AG11: =SUM(AG4:AG10) -> 637.5 | AH11: =SUM(AH4:AH10) -> 237.5 | AI11: =SUM(AI4:AI10) -> 225 | AJ11: =SUM(AJ4:AJ10) -> 150 | AK11: =SUM(AK4:AK10) -> 100 | AL11: =SUM(AL4:AL10) -> 150 | AQ11: =SUM(AE11:AP11) -> 2157.5
A12: FY 2025-26 | Khavda Solar Projects Monthly Commissioning Plan (MWac) | AG12: In May-25 & Jun-25 @1.15 OL & balance 1.37 OL by Jul to Sep-25
A13: Priority | B13: Project | C13: SPV | D13: Plot No | E13: Plot No GP | F13: Category | G13: Category | H13: MMS Type | I13: Module Source | J13: Module Wp | K13: Capacity (MWac) | L13: OL | M13: Capacity (MWdc) | N13: PSS No. | O13: PSS Charging Date | P13: SCOD | Q13: Commissioning as per Growth Plan | R13: Plot Head | S13: Commissioning as per Growth Plan (R5 - 08-Feb-25) | T13: Capex BOQ Release Date | U13: LTA Phase | V13: Expected LTA Operationalization | W13: Plant Code | X13: SUPPLY Plant Code | Y13: SERVICE Plant Code | Z13: Commissioning as per Growth Plan | AA13: Charging Start | AB13: Charging Finish | AD13: Capex NFA Status | AE13: 45748 | AF13: 45778 | AG13: 45809 | AH13: 45839 | AI13: 45870 | AJ13: 45901 | AK13: 45931 | AL13: 45962 | AM13: 45992 | AN13: 46023 | AO13: 46054 | AP13: 46082
A14: P-01 | B14: Google Hybrid | C14: ARE3L | D14: A-6 | E14: A18 | F14: Merchant-Google | G14: Merchant | H14: HSAT | I14: ALMM | J14: 580 | K14: =SUM(AE14:AP14) -> 25 | L14: 1.35 | M14: =L14*K14 -> 33.75 | N14: PSS-08 | O14: 45767 | P14: - | Q14: 45838 | R14: Trilochan Saggu | S14: 45838 | T14: 45615 | U14: Phase - II | V14: 45747 | AH14: 25 | AI14: 0 | AJ14: 0 | AK14: 0 | AL14: 0 | AM14: 0 | AQ14: =SUM(AE14:AP14) -> 25
A15: P-02 | B15: AGEL Merchant | C15: ASEJ6PL | D15: A-6 | E15: A18, S9 | F15: Merchant-Hybrid | G15: Merchant | H15: HSAT | I15: ALMM | J15: 580 | K15: =SUM(AE15:AP15) -> 35 | L15: 1.35 | M15: =L15*K15 -> 47.25 | N15: PSS-08 | O15: =O14 -> 45767 | P15: - | Q15: 45838 | R15: Trilochan Saggu | S15: 45838 | T15: 45615 | U15: Phase - II | V15: 45747 | AH15: 35 | AI15: 0 | AJ15: 0 | AK15: 0 | AL15: 0 | AM15: 0 | AQ15: =SUM(AE15:AP15) -> 35
A16: P-03 | B16: AGEL Hybrid Merchant | C16: ARE48L | D16: S-8 | E16: S7, S8 | F16: Merchant-Hybrid | G16: Merchant | H16: HSAT | I16: ALMM | J16: 580 | K16: =SUM(AE16:AP16) -> 100 | L16: 1.35 | M16: =L16*K16 -> 135 | N16: PSS-09 | O16: Charged | P16: - | Q16: 45838 | R16: Arvind / Dhritiman | S16: 45838 | T16: 45615 | U16: Phase - III | V16: 46022 | AG16: 0 | AH16: 0 | AI16: 50 | AJ16: 0 | AL16: 50 | AM16: 0 | AQ16: =SUM(AE16:AP16) -> 100
A17: P-04 | B17: AGEL Merchant | C17: AHEJ5L | D17: A-15a | E17: A15 | F17: Merchant | G17: Merchant | H17: HSAT | I17: ALMM | J17: 580 | K17: =SUM(AE17:AP17) -> 150 | L17: 1.35 | M17: =L17*K17 -> 202.5 | N17: PSS-08 | O17: =O15 -> 45767 | P17: - | Q17: 45838 | R17: Atul Kumar Kothari | S17: 45838 | T17: 45615 | U17: Phase - II | V17: 45747 | AG17: 0 | AH17: 0 | AI17: 0 | AJ17: 0 | AK17: 50 | AL17: 50 | AM17: 0 | AN17: 50 | AQ17: =SUM(AE17:AP17) -> 150
A18: P-05 | B18: AGEL Hybrid Merchant | C18: AGE26BL | D18: S-5 | E18: S5, S6 | F18: Merchant-Hybrid | G18: Merchant | H18: HSAT | I18: ALMM | J18: 580 | K18: =SUM(AE18:AP18) -> 142 | L18: 1.35 | M18: =L18*K18 -> 191.7 | N18: PSS-10 | O18: =O10 -> Charged | P18: - | Q18: 46022 | R18: P. Raja | S18: 45838 | T18: 45622 | U18: Phase - III | V18: 46022 | AH18: 50 | AI18: 0 | AJ18: 75 | AK18: 17 | AQ18: =SUM(AE18:AP18) -> 142
A19: P-05 | B19: AGEL Merchant | C19: AGE26BL | D19: S-5 | E19: S5, S6 | F19: Merchant | G19: Merchant | H19: HSAT | I19: ALMM | J19: 580 | K19: =SUM(AE19:AP19) -> 150 | L19: 1.35 | M19: =L19*K19 -> 202.5 | N19: PSS-10 | O19: =O11 -> 0 | P19: - | Q19: 46022 | R19: P. Raja | S19: 45838 | T19: 45622 | U19: Phase - III | V19: 46022 | AK19: 45 | AL19: 105 | AQ19: =SUM(AE19:AP19) -> 150
A20: P-06 | B20: AGEL Merchant | C20: AGE24L | D20: S-5 | E20: S5, S6 | F20: Merchant | G20: Merchant | H20: HSAT | I20: ALMM | J20: 580 | K20: =SUM(AE20:AP20) -> 150 | L20: 1.35 | M20: =L20*K20 -> 202.5 | N20: PSS-10 | O20: =O18 -> Charged | P20: - | Q20: 46022 | R20: P. Raja | S20: 45838 | T20: 45622 | U20: Phase - III | V20: 46022 | AG20: 0 | AH20: 0 | AI20: 0 | AJ20: 0 | AK20: 0 | AM20: 0 | AN20: 50 | AO20: 100 | AQ20: =SUM(AE20:AP20) -> 150
A21: P-07 | B21: AGEL Merchant | C21: AGE24L | D21: A-14 | E21: A13, A14, A17 | F21: Merchant | G21: Merchant | H21: HSAT | I21: ALMM | J21: 580 | K21: =SUM(AE21:AP21) -> 150 | L21: 1.35 | M21: =L21*K21 -> 202.5 | N21: PSS-05 | O21: =O9 -> Charged | P21: - | R21: Syed Ali | S21: 45838 | AG21: 0 | AH21: 0 | AI21: 0 | AJ21: 0 | AK21: 0 | AN21: 50 | AO21: 100 | AQ21: =SUM(AE21:AP21) -> 150
A22: P-08 | B22: Cement - Hybrid | C22: ACL | D22: A-1 | E22: A1, A2 | F22: Cement - Hybrid | G22: Group | H22: FT | I22: ALMM | J22: 580 | K22: =SUM(AE22:AP22) -> 125 | L22: 1.36 | M22: =L22*K22 -> 170 | N22: PSS-04 | O22: =O7 -> Charged | P22: - | Q22: 45838 | R22: Rupesh Kumar | S22: 45838 | T22: 45615 | U22: Phase - II | V22: 45747 | AG22: 0 | AH22: 0 | AI22: 75 | AK22: 50 | AL22: 0 | AM22: 0 | AQ22: =SUM(AE22:AP22) -> 125
A23: P-14 | B23: MLP T3 AP | C23: AGE25CL | D23: A-6 | E23: A6 | F23: PPA | G23: PPA | H23: HSAT | I23: China | K23: =SUM(AE23:AP23) -> 75 | L23: 1.35 | M23: =L23*K23 -> 101.25 | N23: PSS-08 | O23: =O15 -> 45767 | P23: 45966 | S23: 45931 | AI23: 75 | AQ23: =SUM(AE23:AP23) -> 75
A24: P-09 | B24: MLP T1 J&K | C24: AGE26AL | D24: A-16 | E24: A16 | F24: PPA | G24: PPA | H24: FT | I24: SEA | K24: =SUM(AE24:AP24) -> 50 | L24: 1.36 | M24: =L24*K24 -> 68 | N24: PSS-06 | O24: 45848 | P24: 45734 | Q24: 45930 | S24: 45930 | T24: 45608 | U24: Phase - I | V24: 45309 | AM24: 50 | AN24: 0 | AO24: 0 | AP24: 0 | AQ24: =SUM(AE24:AP24) -> 50
A25: P-10 | B25: MLP T1 CG | C25: AGE26AL | D25: A-16 | E25: A16 | F25: PPA | G25: PPA | H25: FT | I25: SEA | K25: =SUM(AE25:AP25) -> 200 | L25: 1.36 | M25: =L25*K25 -> 272 | N25: PSS-06 | O25: =O24 -> 45848 | P25: 45734 | Q25: 45930 | S25: 45930 | T25: 45608 | U25: Phase - I | V25: 45309 | AM25: 50 | AN25: 100 | AO25: 50 | AP25: 0 | AQ25: =SUM(AE25:AP25) -> 200
A26: P-11 | B26: MLP T1 TN | C26: AGE26AL | D26: A-16 | E26: A16 | F26: PPA | G26: PPA | H26: FT | I26: SEA | K26: =SUM(AE26:AP26) -> 167 | L26: 1.36 | M26: =L26*K26 -> 227.12 | N26: PSS-06 | O26: =O25 -> 45848 | P26: 45734 | Q26: 45930 | S26: 45930 | T26: 45608 | U26: Phase - I | V26: 45309 | AM26: 50 | AN26: 117 | AO26: 0 | AP26: 0 | AQ26: =SUM(AE26:AP26) -> 167
A27: P-12 | B27: MLP T1 OR | C27: AGE26AL | D27: A-16 | E27: A16 | F27: PPA | G27: PPA | H27: FT | I27: SEA | K27: =SUM(AE27:AP27) -> 333 | L27: 1.36 | M27: =L27*K27 -> 452.88 | N27: PSS-06 | O27: =O26 -> 45848 | P27: 45734 | Q27: 45930 | S27: 45930 | T27: 45608 | U27: Phase - I | V27: 45309 | AN27: 100 | AO27: 100 | AP27: 133 | AQ27: =SUM(AE27:AP27) -> 333
A28: P-13 | B28: MLP T1 TR | C28: AGE26AL | D28: A10a | E28: A9, A10 | F28: PPA | G28: PPA | H28: FT | I28: SEA | K28: =SUM(AE28:AP28) -> 50 | L28: 1.36 | M28: =L28*K28 -> 68 | N28: PSS-03 | O28: Charged | P28: 45561 | Q28: 45838 | S28: 45930 | T28: 45608 | U28: Phase - II | V28: 45747 | AJ28: 50 | AQ28: =SUM(AE28:AP28) -> 50
A29: P-15 | B29: MLP T3 AP | C29: AGE25CL | D29: A-6 | E29: A6 | F29: PPA | G29: PPA | H29: FT | I29: China | K29: =SUM(AE29:AP29) -> 425 | L29: 1.36 | M29: =L29*K29 -> 578 | N29: PSS-08 | O29: =O10 -> Charged | P29: 45966 | S29: 45931 | AN29: 150 | AO29: 150 | AP29: 125 | AQ29: =SUM(AE29:AP29) -> 425
A30: P-16 | B30: AGEL Hybrid Merchant | C30: AHEJ5L | D30: S-4 | E30: Merchant | F30: Merchant | G30: Merchant | H30: HSAT | K30: 300 | L30: 1.35 | M30: =L30*K30 -> 405 | N30: PSS-11 | AM30: 100 | AN30: 100 | AO30: 100 | AQ30: =SUM(AE30:AP30) -> 300
A31: P-17 | B31: =B5 -> MLP AP New | C31: =C5 -> ARE57L | D31: =D5 -> A-11 | E31: PPA | F31: PPA | G31: PPA | H31: HSAT | K31: 350 | L31: 1.35 | M31: =L31*K31 -> 472.5 | N31: =N5 -> PSS-13 | AM31: 150 | AN31: 200 | AQ31: =SUM(AE31:AP31) -> 350
A32: P-18a | B32: KCTL | C32: KCTL | D32: A-15a | E32: Group | F32: Copper | G32: Group | H32: HSAT | K32: 12.5 | L32: 1.35 | M32: =L32*K32 -> 16.875 | N32: PSS-08 | AO32: 12.5 | AQ32: =SUM(AE32:AP32) -> 12.5
A33: P-18b | B33: MCIPL | C33: MCIPL | D33: A-15a | E33: Group | F33: Copper | G33: Group | H33: HSAT | K33: 12.5 | L33: 1.35 | M33: =L33*K33 -> 16.875 | N33: PSS-08 | AO33: 12.5 | AQ33: =SUM(AE33:AP33) -> 12.5
A34: P-19 | B34: AGEL Merchant | C34: ASEJo6PL | D34: A-15a | E34: Merchant | F34: Merchant | G34: Merchant | H34: HSAT | K34: 25 | L34: 1.35 | M34: =L34*K34 -> 33.75 | N34: PSS-08 | AO34: 25 | AQ34: =SUM(AE34:AP34) -> 25
A35: Monthwise FY 25-26 Projects (B) | K35: =SUM(K14:K34) -> 3027 | L35: =SUM(L14:L34) -> 28.42 | M35: =SUM(M14:M34) -> 4099.95 | N35: =SUM(N14:N34) -> 0 | P35: =SUM(P14:P34) -> 320429 | Q35: =SUM(Q14:Q34) -> 596814 | R35: =SUM(R14:R34) -> 0 | S35: =SUM(S14:S34) -> 734054 | T35: =SUM(T14:T34) -> 592981 | U35: =SUM(U14:U34) -> 0 | V35: =SUM(V14:V34) -> 594059 | W35: =SUM(W14:W34) -> 0 | ... AQ35: =SUM(AQ14:AQ34) -> 3027
A37: Monthwise FY 24-26 Projects (A) + (B) | K37: =K35+K11 -> 7072 | M37: =M35+M11 -> 7714.825 | AE37: =AE35+AE11 -> 370 | AF37: =AF35+AF11 -> 287.5 | AG37: =AG35+AG11 -> 637.5 | AH37: =AH35+AH11 -> 347.5 | AI37: =AI35+AI11 -> 425 | AJ37: =AJ35+AJ11 -> 275 | AK37: =AK35+AK11 -> 262 | AL37: =AL35+AL11 -> 355 | ... AP37: =AP35+AP11 -> 258
A38: FY Wise & Quaterly Breakup | K38: =K37 -> 7072 | M38: =M37 -> 7714.825 | AE38: =SUM(AE37:AG37) -> 1295 | AH38: =SUM(AH37:AJ37) -> 1047.5 | AK38: =SUM(AK37:AM37) -> 1017 | AN38: =SUM(AN37:AP37) -> 1825
AE39: =AE38+AH38+AK38+AN38 -> 5184.5
A40: b. For 25-26 Merchant Projects 627 MW commissioning planned in May-25 & Jun-25 to be commissioned at 1.15 DC overloading, and full capacity DC overloading shall be achieved during July-25 to Sep-25 (need to be considered during revenue projections)

Sheet Summary Linked
A1: 8 | B1: AGEL FY 25-26 Commissioning Status Update | K1: For Chairman Budget Purpose @6.5GW +535 MW carryover | W1: 46022
A2: 3 | J2: Monthwise Distribution | Y2: Quarterly Distribution
I3: Plan / Actual | J3: 45748 | K3: 45778 | L3: 45809 | M3: 45839 | N3: 45870 | O3: 45901 | P3: 45931 | Q3: 45962 | R3: 45992 | S3: 46023 | T3: 46054 | U3: 46082 | V3: Total Capacity | W3: Cumm till 30-Nov-25 | Y3: Q1 | Z3: Q2 | AA3: Q3 | AB3: Q4
B4: AGEL Overall FY 2025-26 (1+2) | I4: Plan | J4: =SUM(J5:J7) -> 1114.5 | K4: =SUM(K5:K7) -> 532 | L4: =SUM(L5:L7) -> 1546.4 | M4: =SUM(M5:M7) -> 643.6 | N4: =SUM(N5:N7) -> 26 | O4: =SUM(O5:O7) -> 459 | P4: =SUM(P5:P7) -> 419 | Q4: =SUM(Q5:Q7) -> 655 | ... U4: =SUM(U5:U7) -> 75.9 | V4: =SUM(J4:U4) -> 7072.8 | W4: =SUM(OFFSET(J4,0,0,1,$A$1)) -> 5395.5 | Y4: =SUM(OFFSET($J4,0,0,1,$A$2)) -> 3192.9 | Z4: =SUM(OFFSET($M4,0,0,1,$A$2)) -> 1128.6 | AA4: =SUM(OFFSET($P4,0,0,1,$A$2)) -> 2113 | AB4: =SUM(OFFSET($S4,0,0,1,$A$2)) -> 638.3
I5: PPA | J5: =+J19+J212 -> 582.5 | K5: =+K19+K212 -> 0 | L5: =+L19+L212 -> 475 | M5: =+M19+M212 -> 622.8 | N5: =+N19+N212 -> 26 | O5: =+O19+O212 -> 459 | P5: =+P19+P212 -> 419 | Q5: =+Q19+Q212 -> 351 | ... U5: =+U19+U212 -> 0 | V5: =SUM(J5:U5) -> 4144.3 | W5: =SUM(OFFSET(J5,0,0,1,$A$1)) -> 2935.3 | Y5: =SUM(OFFSET($J5,0,0,1,$A$2)) -> 1057.5 | Z5: =SUM(OFFSET($M5,0,0,1,$A$2)) -> 1107.8 | AA5: =SUM(OFFSET($P5,0,0,1,$A$2)) -> 1679 | AB5: =SUM(OFFSET($S5,0,0,1,$A$2)) -> 300
I6: Merchant | J6: =+J20+J213 -> 506 | K6: =+K20+K213 -> 500.8 | L6: =+L20+L213 -> 646.4 | M6: =+M20+M213 -> 20.8 | N6: =+N20+N213 -> 0 | O6: =+O20+O213 -> 0 | P6: =+P20+P213 -> 0 | Q6: =+Q20+Q213 -> 304 | ... U6: =+U20+U213 -> 75.9 | V6: =SUM(J6:U6) -> 2446.3 | W6: =SUM(OFFSET(J6,0,0,1,$A$1)) -> 1978 | Y6: =SUM(OFFSET($J6,0,0,1,$A$2)) -> 1653.2 | Z6: =SUM(OFFSET($M6,0,0,1,$A$2)) -> 20.8 | AA6: =SUM(OFFSET($P6,0,0,1,$A$2)) -> 434 | AB6: =SUM(OFFSET($S6,0,0,1,$A$2)) -> 338.3
I7: Group | J7: =+J21+J214 -> 26 | K7: =+K21+K214 -> 31.2 | L7: =+L21+L214 -> 425 | M7: =+M21+M214 -> 0 | N7: =+N21+N214 -> 0 | O7: =+O21+O214 -> 0 | P7: =+P21+P214 -> 0 | Q7: =+Q21+Q214 -> 0 | ... U7: =+U21+U214 -> 0 | V7: =SUM(J7:U7) -> 482.2 | W7: =SUM(OFFSET(J7,0,0,1,$A$1)) -> 482.2 | Y7: =SUM(OFFSET($J7,0,0,1,$A$2)) -> 482.2 | Z7: =SUM(OFFSET($M7,0,0,1,$A$2)) -> 0 | AA7: =SUM(OFFSET($P7,0,0,1,$A$2)) -> 0 | AB7: =SUM(OFFSET($S7,0,0,1,$A$2)) -> 0
I8: Rephase | J8: =SUM(J9:J11) -> 474 | K8: =SUM(K9:K11) -> 313.5 | L8: =SUM(L9:L11) -> 848.7 | M8: =SUM(M9:M11) -> 575.5 | N8: =SUM(N9:N11) -> 653 | O8: =SUM(O9:O11) -> 353 | P8: =SUM(P9:P11) -> 366 | Q8: =SUM(Q9:Q11) -> 459 | ... U8: =SUM(U9:U11) -> 396.3 | V8: =SUM(J8:U8) -> 7072.8 | W8: =SUM(OFFSET(J8,0,0,1,$A$1)) -> 4042.7 | Y8: =SUM(OFFSET($J8,0,0,1,$A$2)) -> 1636.2 | Z8: =SUM(OFFSET($M8,0,0,1,$A$2)) -> 1581.5 | AA8: =SUM(OFFSET($P8,0,0,1,$A$2)) -> 1607.8 | AB8: =SUM(OFFSET($S8,0,0,1,$A$2)) -> 2247.3
I9: PPA | J9: =+J23+J216 -> 320 | K9: =+K23+K216 -> 162.5 | L9: =+L23+L216 -> 462.5 | M9: =+M23+M216 -> 187.5 | N9: =+N23+N216 -> 150 | O9: =+O23+O216 -> 200 | P9: =+P23+P216 -> 100 | Q9: =+Q23+Q216 -> 254 | ... U9: =+U23+U216 -> 258 | V9: =SUM(J9:U9) -> 4144.3 | W9: =SUM(OFFSET(J9,0,0,1,$A$1)) -> 1836.5 | Y9: =SUM(OFFSET($J9,0,0,1,$A$2)) -> 945 | Z9: =SUM(OFFSET($M9,0,0,1,$A$2)) -> 537.5 | AA9: =SUM(OFFSET($P9,0,0,1,$A$2)) -> 1136.8 | AB9: =SUM(OFFSET($S9,0,0,1,$A$2)) -> 1525
I10: Merchant | J10: =+J24+J217 -> 154 | K10: =+K24+K217 -> 125 | L10: =+L24+L217 -> 355 | M10: =+M24+M217 -> 238 | N10: =+N24+N217 -> 278 | O10: =+O24+O217 -> 153 | P10: =+P24+P217 -> 216 | Q10: =+Q24+Q217 -> 205 | ... U10: =+U24+U217 -> 138.3 | V10: =SUM(J10:U10) -> 2446.3 | W10: =SUM(OFFSET(J10,0,0,1,$A$1)) -> 1724 | Y10: =SUM(OFFSET($J10,0,0,1,$A$2)) -> 634 | Z10: =SUM(OFFSET($M10,0,0,1,$A$2)) -> 669 | AA10: =SUM(OFFSET($P10,0,0,1,$A$2)) -> 421 | AB10: =SUM(OFFSET($S10,0,0,1,$A$2)) -> 722.3
I11: Group | J11: =+J25+J218 -> 0 | K11: =+K25+K218 -> 26 | L11: =+L25+L218 -> 31.2 | M11: =+M25+M218 -> 150 | N11: =+N25+N218 -> 225 | O11: =+O25+O218 -> 0 | P11: =+P25+P218 -> 50 | Q11: =+Q25+Q218 -> 0 | ... U11: =+U25+U218 -> 0 | V11: =SUM(J11:U11) -> 482.2 | W11: =SUM(OFFSET(J11,0,0,1,$A$1)) -> 482.2 | Y11: =SUM(OFFSET($J11,0,0,1,$A$2)) -> 57.2 | Z11: =SUM(OFFSET($M11,0,0,1,$A$2)) -> 375 | AA11: =SUM(OFFSET($P11,0,0,1,$A$2)) -> 50 | AB11: =SUM(OFFSET($S11,0,0,1,$A$2)) -> 0
I12: Actual / Fcst | J12: =SUM(J13:J15) -> 474 | K12: =SUM(K13:K15) -> 313.5 | L12: =SUM(L13:L15) -> 848.7 | M12: =SUM(M13:M15) -> 127.6 | N12: =SUM(N13:N15) -> 537.3 | O12: =SUM(O13:O15) -> 531.2 | P12: =SUM(P13:P15) -> 203 | Q12: =SUM(Q13:Q15) -> 333.2 | ... U12: =SUM(U13:U15) -> 910.1 | V12: =SUM(J12:U12) -> 6588.8 | W12: =SUM(OFFSET(J12,0,0,1,$A$1)) -> 3368.5 | Y12: =SUM(OFFSET($J12,0,0,1,$A$2)) -> 1636.2 | Z12: =SUM(OFFSET($M12,0,0,1,$A$2)) -> 1196.1 | AA12: =SUM(OFFSET($P12,0,0,1,$A$2)) -> 1018.4 | AB12: =SUM(OFFSET($S12,0,0,1,$A$2)) -> 2738.1
I13: PPA | J13: =+J27+J220 -> 320 | K13: =+K27+K220 -> 162.5 | L13: =+L27+L220 -> 462.5 | M13: =+M27+M220 -> 0 | N13: =+N27+N220 -> 137.5 | O13: =+O27+O220 -> 175 | P13: =+P27+P220 -> 203 | Q13: =+Q27+Q220 -> 246.8 | ... U13: =+U27+U220 -> 745.8 | V13: =SUM(J13:U13) -> 3660.3 | W13: =SUM(OFFSET(J13,0,0,1,$A$1)) -> 1707.3 | Y13: =SUM(OFFSET($J13,0,0,1,$A$2)) -> 945 | Z13: =SUM(OFFSET($M13,0,0,1,$A$2)) -> 312.5 | AA13: =SUM(OFFSET($P13,0,0,1,$A$2)) -> 657 | AB13: =SUM(OFFSET($S13,0,0,1,$A$2)) -> 1745.8
I14: Merchant | J14: =+J28+J221 -> 154 | K14: =+K28+K221 -> 125 | L14: =+L28+L221 -> 355 | M14: =+M28+M221 -> 127.6 | N14: =+N28+N221 -> 249.8 | O14: =+O28+O221 -> 306.2 | P14: =+P28+P221 -> 0 | Q14: =+Q28+Q221 -> 86.4 | ... U14: =+U28+U221 -> 164.3 | V14: =SUM(J14:U14) -> 2446.3 | W14: =SUM(OFFSET(J14,0,0,1,$A$1)) -> 1404 | Y14: =SUM(OFFSET($J14,0,0,1,$A$2)) -> 634 | Z14: =SUM(OFFSET($M14,0,0,1,$A$2)) -> 683.6 | AA14: =SUM(OFFSET($P14,0,0,1,$A$2)) -> 136.4 | AB14: =SUM(OFFSET($S14,0,0,1,$A$2)) -> 992.3
I15: Group | J15: =+J29+J222 -> 0 | K15: =+K29+K222 -> 26 | L15: =+L29+L222 -> 31.2 | M15: =+M29+M222 -> 0 | N15: =+N29+N222 -> 150 | O15: =+O29+O222 -> 50 | P15: =+P29+P222 -> 0 | Q15: =+Q29+Q222 -> 0 | ... U15: =+U29+U222 -> 0 | V15: =SUM(J15:U15) -> 482.2 | W15: =SUM(OFFSET(J15,0,0,1,$A$1)) -> 257.2 | Y15: =SUM(OFFSET($J15,0,0,1,$A$2)) -> 57.2 | Z15: =SUM(OFFSET($M15,0,0,1,$A$2)) -> 200 | AA15: =SUM(OFFSET($P15,0,0,1,$A$2)) -> 225 | AB15: =SUM(OFFSET($S15,0,0,1,$A$2)) -> 0
I17: Plan / Actual | J17: 45748 | K17: 45778 | L17: 45809 | M17: 45839 | N17: 45870 | O17: 45901 | P17: 45931 | Q17: 45962 | R17: 45992 | S17: 46023 | T17: 46054 | U17: 46082 | V17: Total Capacity | W17: =+W3 -> Cumm till 30-Nov-25 | Y17: Q1 | Z17: Q2 | AA17: Q3 | AB17: Q4
B18: 1. AGEL Overall Solar FY 2025-26 (A + B + C) | I18: Plan | J18: =SUM(J19:J21) -> 932.5 | K18: =SUM(K19:K21) -> 350 | L18: =SUM(L19:L21) -> 1302 | M18: =SUM(M19:M21) -> 550 | N18: =SUM(N19:N21) -> 0 | O18: =SUM(O19:O21) -> 433 | P18: =SUM(P19:P21) -> 367 | Q18: =SUM(Q19:Q21) -> 525 | ... U18: =SUM(U19:U21) -> 0 | V18: =SUM(J18:U18) -> 5868.5 | W18: =SUM(OFFSET(J18,0,0,1,$A$1)) -> 4459.5 | Y18: =SUM(OFFSET($J18,0,0,1,$A$2)) -> 2584.5 | Z18: =SUM(OFFSET($M18,0,0,1,$A$2)) -> 983 | AA18: =SUM(OFFSET($P18,0,0,1,$A$2)) -> 1801 | AB18: =SUM(OFFSET($S18,0,0,1,$A$2)) -> 500
I19: PPA | J19: =J107+J134 -> 582.5 | K19: =K107+K134+K152 -> 0 | L19: =L107+L134+L152 -> 475 | M19: =M107+M134+M152 -> 550 | N19: =N107+N134+N152 -> 0 | O19: =O107+O134+O152 -> 433 | P19: =P107+P134+P152 -> 367 | Q19: =Q107+Q134+Q152 -> 325 | R19: =R107+R134+R152 -> 909 | ... U19: =U107+U134+U152 -> 0 | V19: =SUM(J19:U19) -> 3941.5 | W19: =SUM(OFFSET(J19,0,0,1,$A$1)) -> 2732.5 | Y19: =SUM(OFFSET($J19,0,0,1,$A$2)) -> 1057.5 | Z19: =SUM(OFFSET($M19,0,0,1,$A$2)) -> 983 | AA19: =SUM(OFFSET($P19,0,0,1,$A$2)) -> 1601 | AB19: =SUM(OFFSET($S19,0,0,1,$A$2)) -> 300
I20: Merchant | J20: =J108+J135 -> 350 | K20: =K108+K135+K153 -> 350 | L20: =L108+L135+L153 -> 402 | M20: =M108+M135+M153 -> 0 | N20: =N108+N135+N153 -> 0 | O20: =O108+O135+O153 -> 0 | P20: =P108+P135+P153 -> 0 | Q20: =Q108+Q135+Q153 -> 200 | R20: =R108+R135+R153 -> 0 | ... U20: =U108+U135+U153 -> 0 | V20: =SUM(J20:U20) -> 1502 | W20: =SUM(OFFSET(J20,0,0,1,$A$1)) -> 1302 | Y20: =SUM(OFFSET($J20,0,0,1,$A$2)) -> 1102 | Z20: =SUM(OFFSET($M20,0,0,1,$A$2)) -> 0 | AA20: =SUM(OFFSET($P20,0,0,1,$A$2)) -> 200 | AB20: =SUM(OFFSET($S20,0,0,1,$A$2)) -> 200
I21: Group | J21: =J109+J136 -> 0 | K21: =K109+K136+K154 -> 0 | L21: =L109+L136+L154 -> 425 | M21: =M109+M136+M154 -> 0 | N21: =N109+N136+N154 -> 0 | O21: =O109+O136+O154 -> 0 | P21: =P109+P136+P154 -> 0 | Q21: =Q109+Q136+Q154 -> 0 | R21: =R109+R136+R154 -> 0 | ... U21: =U109+U136+U154 -> 0 | V21: =SUM(J21:U21) -> 425 | W21: =SUM(OFFSET(J21,0,0,1,$A$1)) -> 425 | Y21: =SUM(OFFSET($J21,0,0,1,$A$2)) -> 425 | Z21: =SUM(OFFSET($M21,0,0,1,$A$2)) -> 0 | AA21: =SUM(OFFSET($P21,0,0,1,$A$2)) -> 0 | AB21: =SUM(OFFSET($S21,0,0,1,$A$2)) -> 0
I22: Rephase | J22: =SUM(J23:J25) -> 370 | K22: =SUM(K23:K25) -> 287.5 | L22: =SUM(L23:L25) -> 687.5 | M22: =SUM(M23:M25) -> 497.5 | N22: =SUM(N23:N25) -> 575 | O22: =SUM(O23:O25) -> 275 | P22: =SUM(P23:P25) -> 262 | Q22: =SUM(Q23:Q25) -> 355 | ... U22: =SUM(U23:U25) -> 258 | V22: =SUM(J22:U22) -> 5868.5 | W22: =SUM(OFFSET(J22,0,0,1,$A$1)) -> 3309.5 | Y22: =SUM(OFFSET($J22,0,0,1,$A$2)) -> 1345 | Z22: =SUM(OFFSET($M22,0,0,1,$A$2)) -> 1347.5 | AA22: =SUM(OFFSET($P22,0,0,1,$A$2)) -> 1301 | AB22: =SUM(OFFSET($S22,0,0,1,$A$2)) -> 1875
I23: PPA | J23: =J111+J138 -> 320 | K23: =K111+K138+K156 -> 162.5 | L23: =L111+L138+L156 -> 462.5 | M23: =M111+M138+M156 -> 187.5 | N23: =N111+N138+N156 -> 150 | O23: =O111+O138+O156 -> 200 | P23: =P111+P138+P156 -> 100 | Q23: =Q111+Q138+Q156 -> 150 | R23: =R111+R138+R156 -> 684 | ... U23: =U111+U138+U156 -> 258 | V23: =SUM(J23:U23) -> 3941.5 | W23: =SUM(OFFSET(J23,0,0,1,$A$1)) -> 1732.5 | Y23: =SUM(OFFSET($J23,0,0,1,$A$2)) -> 945 | Z23: =SUM(OFFSET($M23,0,0,1,$A$2)) -> 537.5 | AA23: =SUM(OFFSET($P23,0,0,1,$A$2)) -> 934 | AB23: =SUM(OFFSET($S23,0,0,1,$A$2)) -> 1525
I24: Merchant | J24: =J112+J139 -> 50 | K24: =K112+K139+K157 -> 125 | L24: =L112+L139+L157 -> 225 | M24: =M112+M139+M157 -> 160 | N24: =N112+N139+N157 -> 200 | O24: =O112+O139+O157 -> 75 | P24: =P112+P139+P157 -> 112 | Q24: =Q112+Q139+Q157 -> 205 | R24: =R112+R139+R157 -> 0 | ... U24: =U112+U139+U157 -> 0 | V24: =SUM(J24:U24) -> 1502 | W24: =SUM(OFFSET(J24,0,0,1,$A$1)) -> 1152 | Y24: =SUM(OFFSET($J24,0,0,1,$A$2)) -> 400 | Z24: =SUM(OFFSET($M24,0,0,1,$A$2)) -> 435 | AA24: =SUM(OFFSET($P24,0,0,1,$A$2)) -> 317 | AB24: =SUM(OFFSET($S24,0,0,1,$A$2)) -> 350
I25: Group | J25: =J113+J140 -> 0 | K25: =K113+K140+K158 -> 0 | L25: =L113+L140+L158 -> 0 | M25: =M113+M140+M158 -> 150 | N25: =N113+N140+N158 -> 225 | O25: =O113+O140+O158 -> 0 | P25: =P113+P140+P158 -> 50 | Q25: =Q113+Q140+Q158 -> 0 | R25: =R113+R140+R158 -> 0 | ... U25: =U113+U140+U158 -> 0 | V25: =SUM(J25:U25) -> 425 | W25: =SUM(OFFSET(J25,0,0,1,$A$1)) -> 425 | Y25: =SUM(OFFSET($J25,0,0,1,$A$2)) -> 0 | Z25: =SUM(OFFSET($M25,0,0,1,$A$2)) -> 375 | AA25: =SUM(OFFSET($P25,0,0,1,$A$2)) -> 50 | AB25: =SUM(OFFSET($S25,0,0,1,$A$2)) -> 0
I26: Actual / Fcst | J26: =SUM(J27:J29) -> 370 | K26: =SUM(K27:K29) -> 287.5 | L26: =SUM(L27:L29) -> 687.5 | M26: =SUM(M27:M29) -> 60 | N26: =SUM(N27:N29) -> 412.5 | O26: =SUM(O27:O29) -> 500 | P26: =SUM(P27:P29) -> 125 | Q26: =SUM(Q27:Q29) -> 250 | ... U26: =SUM(U27:U29) -> 725 | V26: =SUM(J26:U26) -> 5384.5 | W26: =SUM(OFFSET(J26,0,0,1,$A$1)) -> 2692.5 | Y26: =SUM(OFFSET($J26,0,0,1,$A$2)) -> 1345 | Z26: =SUM(OFFSET($M26,0,0,1,$A$2)) -> 972.5 | AA26: =SUM(OFFSET($P26,0,0,1,$A$2)) -> 800 | AB26: =SUM(OFFSET($S26,0,0,1,$A$2)) -> 2267
I27: PPA | J27: =J115+J142 -> 320 | K27: =K115+K142+K160 -> 162.5 | L27: =L115+L142+L160 -> 462.5 | M27: =M115+M142+M160 -> 0 | N27: =N115+N142+N160 -> 137.5 | O27: =O115+O142+O160 -> 175 | P27: =P115+P142+P160 -> 125 | Q27: =Q115+Q142+Q160 -> 200 | R27: =R115+R142+R160 -> 150 | ... U27: =U115+U142+U160 -> 725 | V27: =SUM(J27:U27) -> 3457.5 | W27: =SUM(OFFSET(J27,0,0,1,$A$1)) -> 1582.5 | Y27: =SUM(OFFSET($J27,0,0,1,$A$2)) -> 945 | Z27: =SUM(OFFSET($M27,0,0,1,$A$2)) -> 312.5 | AA27: =SUM(OFFSET($P27,0,0,1,$A$2)) -> 475 | AB27: =SUM(OFFSET($S27,0,0,1,$A$2)) -> 1725
I28: Merchant | J28: =J116+J143 -> 50 | K28: =K116+K143+K161 -> 125 | L28: =L116+L143+L161 -> 225 | M28: =M116+M143+M161 -> 60 | N28: =N116+N143+N161 -> 125 | O28: =O116+O143+O161 -> 275 | P28: =P116+P143+P161 -> 0 | Q28: =Q116+Q143+Q161 -> 50 | R28: =R116+R143+R161 -> 50 | ... U28: =U116+U143+U161 -> 0 | V28: =SUM(J28:U28) -> 1502 | W28: =SUM(OFFSET(J28,0,0,1,$A$1)) -> 910 | Y28: =SUM(OFFSET($J28,0,0,1,$A$2)) -> 400 | Z28: =SUM(OFFSET($M28,0,0,1,$A$2)) -> 460 | AA28: =SUM(OFFSET($P28,0,0,1,$A$2)) -> 100 | AB28: =SUM(OFFSET($S28,0,0,1,$A$2)) -> 542
I29: Group | J29: =J117+J144 -> 0 | K29: =K117+K144+K162 -> 0 | L29: =L117+L144+L162 -> 0 | M29: =M117+M144+M162 -> 0 | N29: =N117+N144+N162 -> 150 | O29: =O117+O144+O162 -> 50 | P29: =P117+P144+P162 -> 0 | Q29: =Q117+Q144+Q162 -> 0 | R29: =R117+R144+R162 -> 225 | ... U29: =U117+U144+U162 -> 0 | V29: =SUM(J29:U29) -> 425 | W29: =SUM(OFFSET(J29,0,0,1,$A$1)) -> 200 | Y29: =SUM(OFFSET($J29,0,0,1,$A$2)) -> 0 | Z29: =SUM(OFFSET($M29,0,0,1,$A$2)) -> 200 | AA29: =SUM(OFFSET($P29,0,0,1,$A$2)) -> 225 | AB29: =SUM(OFFSET($S29,0,0,1,$A$2)) -> 0
B31: S. No. | C31: Project Name | D31: SPV | E31: Type | F31: Plot / Location / PSS | G31: Capacity | H31: Type | I31: Plan Actual | J31: 45748 | K31: 45778 | L31: 45809 | M31: 45839 | N31: 45870 | O31: 45901 | P31: 45931 | Q31: 45962 | R31: 45992 | S31: 46023 | T31: 46054 | U31: 46082 | V31: Total Capacity | W31: =+W17 -> Cumm till 30-Nov-25 | Y31: Q1 | Z31: Q2 | AA31: Q3 | AB31: Q4
B32: A. Khavda Solar Projects
B33: 1 | C33: AGEL Merchant | D33: ARE56L | E33: Merchant | F33: S-08 | G33: 250 | H33: Merchant | I33: Plan | J33: ='KH Solar Plan'!AF4 -> 150 | K33: ='KH Solar Plan'!AG4 -> 100 | L33: ='KH Solar Plan'!AH4 -> 0 | M33: ='KH Solar Plan'!AI4 -> 0 | N33: ='KH Solar Plan'!AJ4 -> 0 | O33: ='KH Solar Plan'!AK4 -> 0 | P33: ='KH Solar Plan'!AL4 -> 0 | Q33: ='KH Solar Plan'!AM4 -> 0 | ... U33: ='KH Solar Plan'!AQ4 -> 0 | V33: =SUM(J33:U33) -> 250 | W33: =SUM(OFFSET(J33,0,0,1,$A$1)) -> 250 | Y33: =SUM(OFFSET($J33,0,0,1,$A$2)) -> 250 | Z33: =SUM(OFFSET($M33,0,0,1,$A$2)) -> 0 | AA33: =SUM(OFFSET($P33,0,0,1,$A$2)) -> 0 | AB33: =SUM(OFFSET($S33,0,0,1,$A$2)) -> 0
H34: Merchant | I34: Rephase | J34: ='KH Solar Rephase'!AE4 -> 0 | K34: ='KH Solar Rephase'!AF4 -> 75 | L34: ='KH Solar Rephase'!AG4 -> 50 | M34: ='KH Solar Rephase'!AH4 -> 50 | N34: ='KH Solar Rephase'!AI4 -> 75 | O34: ='KH Solar Rephase'!AJ4 -> 0 | P34: ='KH Solar Rephase'!AK4 -> 0 | Q34: ='KH Solar Rephase'!AL4 -> 0 | ... U34: ='KH Solar Rephase'!AP4 -> 0 | V34: =SUM(J34:U34) -> 250 | W34: =SUM(OFFSET(J34,0,0,1,$A$1)) -> 250 | Y34: =SUM(OFFSET($J34,0,0,1,$A$2)) -> 125 | Z34: =SUM(OFFSET($M34,0,0,1,$A$2)) -> 125 | AA34: =SUM(OFFSET($P34,0,0,1,$A$2)) -> 0 | AB34: =SUM(OFFSET($S34,0,0,1,$A$2)) -> 0
H35: Merchant | I35: Actual / Fcst | J35: ='KH Solar Actual'!O5 -> 0 | K35: ='KH Solar Actual'!P5 -> 75 | L35: ='KH Solar Actual'!Q5 -> 50 | M35: ='KH Solar Actual'!R5 -> 0 | N35: ='KH Solar Actual'!S5 -> 125 | O35: ='KH Solar Actual'!T5 -> 0 | P35: ='KH Solar Actual'!U5 -> 0 | Q35: ='KH Solar Actual'!V5 -> 0 | ... U35: ='KH Solar Actual'!Z5 -> 0 | V35: =SUM(J35:U35) -> 250 | W35: =SUM(OFFSET(J35,0,0,1,$A$1)) -> 250 | Y35: =SUM(OFFSET($J35,0,0,1,$A$2)) -> 125 | Z35: =SUM(OFFSET($M35,0,0,1,$A$2)) -> 125 | AA35: =SUM(OFFSET($P35,0,0,1,$A$2)) -> 0 | AB35: =SUM(OFFSET($S35,0,0,1,$A$2)) -> 0
B36: 2 | C36: AGEL Merchant | D36: ARE56L | E36: Merchant | F36: A-02 | G36: 50 | H36: Merchant | I36: Plan | J36: ='KH Solar Plan'!AF5 -> 50 | K36: ='KH Solar Plan'!AG5 -> 0 | L36: ='KH Solar Plan'!AH5 -> 0 | M36: ='KH Solar Plan'!AI5 -> 0 | N36: ='KH Solar Plan'!AJ5 -> 0 | O36: ='KH Solar Plan'!AK5 -> 0 | P36: ='KH Solar Plan'!AL5 -> 0 | Q36: ='KH Solar Plan'!AM5 -> 0 | ... U36: ='KH Solar Plan'!AQ5 -> 0 | V36: =SUM(J36:U36) -> 50 | W36: =SUM(OFFSET(J36,0,0,1,$A$1)) -> 50 | Y36: =SUM(OFFSET($J36,0,0,1,$A$2)) -> 50 | Z36: =SUM(OFFSET($M36,0,0,1,$A$2)) -> 0 | AA36: =SUM(OFFSET($P36,0,0,1,$A$2)) -> 0 | AB36: =SUM(OFFSET($S36,0,0,1,$A$2)) -> 0
B37: 2 | C37: AGEL Merchant | D37: ARE56L | E37: Merchant | F37: A-02 | H37: Merchant | I37: Rephase | J37: ='KH Solar Rephase'!AE5 -> 0 | K37: ='KH Solar Rephase'!AF5 -> 50 | L37: ='KH Solar Rephase'!AG5 -> 0 | M37: ='KH Solar Rephase'!AH5 -> 0 | N37: ='KH Solar Rephase'!AI5 -> 0 | O37: ='KH Solar Rephase'!AJ5 -> 0 | P37: ='KH Solar Rephase'!AK5 -> 0 | Q37: ='KH Solar Rephase'!AL5 -> 0 | ... U37: ='KH Solar Rephase'!AP5 -> 0 | V37: =SUM(J37:U37) -> 50 | W37: =SUM(OFFSET(J37,0,0,1,$A$1)) -> 50 | Y37: =SUM(OFFSET($J37,0,0,1,$A$2)) -> 50 | Z37: =SUM(OFFSET($M37,0,0,1,$A$2)) -> 0 | AA37: =SUM(OFFSET($P37,0,0,1,$A$2)) -> 0 | AB37: =SUM(OFFSET($S37,0,0,1,$A$2)) -> 0
B38: 2 | C38: AGEL Merchant | D38: ARE56L | E38: Merchant | F38: A-02 | H38: Merchant | I38: Actual / Fcst | J38: ='KH Solar Actual'!O6 -> 0 | K38: ='KH Solar Actual'!P6 -> 50 | L38: ='KH Solar Actual'!Q6 -> 0 | M38: ='KH Solar Actual'!R6 -> 0 | N38: ='KH Solar Actual'!S6 -> 0 | O38: ='KH Solar Actual'!T6 -> 0 | P38: ='KH Solar Actual'!U6 -> 0 | Q38: ='KH Solar Actual'!V6 -> 0 | ... U38: ='KH Solar Actual'!Z6 -> 0 | V38: =SUM(J38:U38) -> 50 | W38: =SUM(OFFSET(J38,0,0,1,$A$1)) -> 50 | Y38: =SUM(OFFSET($J38,0,0,1,$A$2)) -> 50 | Z38: =SUM(OFFSET($M38,0,0,1,$A$2)) -> 0 | AA38: =SUM(OFFSET($P38,0,0,1,$A$2)) -> 0 | AB38: =SUM(OFFSET($S38,0,0,1,$A$2)) -> 0
B39: 3 | C39: MLP AP New | D39: ARE57L | E39: PPA | F39: A-11 | G39: 187.5 | H39: PPA | I39: Plan | J39: ='KH Solar Plan'!AF6 -> 187.5 | K39: ='KH Solar Plan'!AG6 -> 0 | L39: ='KH Solar Plan'!AH6 -> 0 | M39: ='KH Solar Plan'!AI6 -> 0 | N39: ='KH Solar Plan'!AJ6 -> 0 | O39: ='KH Solar Plan'!AK6 -> 0 | P39: ='KH Solar Plan'!AL6 -> 0 | Q39: ='KH Solar Plan'!AM6 -> 0 | ... U39: ='KH Solar Plan'!AQ6 -> 0 | V39: =SUM(J39:U39) -> 187.5 | W39: =SUM(OFFSET(J39,0,0,1,$A$1)) -> 187.5 | Y39: =SUM(OFFSET($J39,0,0,1,$A$2)) -> 187.5 | Z39: =SUM(OFFSET($M39,0,0,1,$A$2)) -> 0 | AA39: =SUM(OFFSET($P39,0,0,1,$A$2)) -> 0 | AB39: =SUM(OFFSET($S39,0,0,1,$A$2)) -> 0
B40: 3 | C40: MLP AP New | D40: ARE57L | E40: PPA | F40: A-11 | H40: PPA | I40: Rephase | J40: ='KH Solar Rephase'!AE6 -> 75 | K40: ='KH Solar Rephase'!AF6 -> 112.5 | L40: ='KH Solar Rephase'!AG6 -> 0 | M40: ='KH Solar Rephase'!AH6 -> 0 | N40: ='KH Solar Rephase'!AI6 -> 0 | O40: ='KH Solar Rephase'!AJ6 -> 0 | P40: ='KH Solar Rephase'!AK6 -> 0 | Q40: ='KH Solar Rephase'!AL6 -> 0 | ... U40: ='KH Solar Rephase'!AP6 -> 0 | V40: =SUM(J40:U40) -> 187.5 | W40: =SUM(OFFSET(J40,0,0,1,$A$1)) -> 187.5 | Y40: =SUM(OFFSET($J40,0,0,1,$A$2)) -> 187.5 | Z40: =SUM(OFFSET($M40,0,0,1,$A$2)) -> 0 | AA40: =SUM(OFFSET($P40,0,0,1,$A$2)) -> 0 | AB40: =SUM(OFFSET($S40,0,0,1,$A$2)) -> 0
B41: 3 | C41: MLP AP New | D41: ARE57L | E41: PPA | F41: A-11 | H41: PPA | I41: Actual / Fcst | J41: ='KH Solar Actual'!O7 -> 75 | K41: ='KH Solar Actual'!P7 -> 112.5 | L41: ='KH Solar Actual'!Q7 -> 0 | M41: ='KH Solar Actual'!R7 -> 0 | N41: ='KH Solar Actual'!S7 -> 0 | O41: ='KH Solar Actual'!T7 -> 0 | P41: ='KH Solar Actual'!U7 -> 0 | Q41: ='KH Solar Actual'!V7 -> 0 | ... U41: ='KH Solar Actual'!Z7 -> 0 | V41: =SUM(J41:U41) -> 187.5 | W41: =SUM(OFFSET(J41,0,0,1,$A$1)) -> 187.5 | Y41: =SUM(OFFSET($J41,0,0,1,$A$2)) -> 187.5 | Z41: =SUM(OFFSET($M41,0,0,1,$A$2)) -> 0 | AA41: =SUM(OFFSET($P41,0,0,1,$A$2)) -> 0 | AB41: =SUM(OFFSET($S41,0,0,1,$A$2)) -> 0
B42: 4 | C42: MLP AP New | D42: ARE57L | E42: PPA | F42: A-12 | G42: 350 | H42: PPA | I42: Plan | J42: ='KH Solar Plan'!AF7 -> 0 | K42: ='KH Solar Plan'!AG7 -> 0 | L42: ='KH Solar Plan'!AH7 -> 100 | M42: ='KH Solar Plan'!AI7 -> 250 | N42: ='KH Solar Plan'!AJ7 -> 0 | O42: ='KH Solar Plan'!AK7 -> 0 | P42: ='KH Solar Plan'!AL7 -> 0 | Q42: ='KH Solar Plan'!AM7 -> 0 | ... U42: ='KH Solar Plan'!AQ7 -> 0 | V42: =SUM(J42:U42) -> 350 | W42: =SUM(OFFSET(J42,0,0,1,$A$1)) -> 350 | Y42: =SUM(OFFSET($J42,0,0,1,$A$2)) -> 100 | Z42: =SUM(OFFSET($M42,0,0,1,$A$2)) -> 250 | AA42: =SUM(OFFSET($P42,0,0,1,$A$2)) -> 0 | AB42: =SUM(OFFSET($S42,0,0,1,$A$2)) -> 0
...

Sheet KH Wind Actual
I1: Out of 57.2 MW (11 WTGs), 7 WTG TR Done in Nov-25, but COD in Dec-25
H2: Forecast | I2: Actual
A3: FY 2025-26 | Khavda Wind Projects Monthly Commissioning Plan (MWac) | R3: Date: 30-Dec-25
A4: Sl. | B4: Project | C4: SPV | D4: Category | E4: Capacity (MW) | F4: WTG Nos. | G4: PSS No. | H4: 45748 | I4: 45778 | J4: 45809 | K4: 45839 | L4: 45870 | M4: 45901 | N4: 45931 | O4: 45962 | P4: 45992 | Q4: 46023 | R4: 46054 | S4: 46082
A5: 1 | B5: AGEL Merchant (Wind) | C5: AGE24L | D5: Merchant | E5: =SUM(H5:S5) -> 52 | F5: =E5/5.2 -> 10 | G5: PSS-04 | H5: =10*5.2 -> 52
A6: 2 | B6: Hybrid Cement (Wind) | C6: ACL | D6: Group | E6: =SUM(H6:S6) -> 57.2 | F6: =E6/5.2 -> 11 | G6: PSS-04 | I6: 26 | J6: =6*5.2 -> 31.2
A7: 3 | B7: AGEL Merchant (Wind) | C7: AHEJ5L | D7: Merchant | E7: =SUM(H7:S7) -> 62.4 | F7: =E7/5.2 -> 12 | G7: PSS-04 | H7: =10*5.2 -> 52 | J7: =2*5.2 -> 10.4
A8: 4 | B8: AGEL Hybrid Merchant (Wind) | C8: AGE26BL | D8: Merchant | E8: =SUM(H8:S8) -> 156 | F8: =E8/5.2 -> 30 | G8: PSS-10 | J8: =23*5.2 -> 119.6 | K8: =5*5.2 -> 26 | R8: =2*5.2 -> 10.4
A9: 5 | B9: AGEL Merchant (Wind) | C9: AHEJ5L | D9: Merchant | E9: =SUM(H9:S9) -> 67.6 | F9: =E9/5.2 -> 13 | G9: PSS-08 | M9: =6*5.2 -> 31.2 | O9: =6*5.2 -> 31.2 | Q9: =1*5.2 -> 5.2
A10: 6 | B10: AGEL Merchant (Wind) | C10: ARE41L | D10: Merchant | E10: =SUM(H10:S10) -> 130 | F10: =E10/5.2 -> 25 | G10: PSS-08 | L10: =24*5.2 -> 124.8 | O10: =1*5.2 -> 5.2
A11: 7 | B11: Google Hybrid (Wind) | C11: ARE3L | D11: Merchant | E11: =SUM(H11:S11) -> 15.6 | F11: =E11/5.2 -> 3 | G11: PSS-08 | K11: =3*5.2 -> 15.6
A12: 8 | B12: Google Hybrid (Wind) | C12: ARE3L | D12: Merchant | E12: =SUM(H12:S12) -> 26 | F12: =E12/5.2 -> 5 | G12: PSS-08 | K12: =5*5.2 -> 26
A13: 9 | B13: AGEL Hybrid Merchant (Wind) | C13: ASEJ6PL | D13: Merchant | E13: =SUM(H13:S13) -> 62.4 | F13: =E13/5.2 -> 12 | G13: PSS-08 | Q13: =6*5.2 -> 31.2 | R13: =4*5.2 -> 20.8 | S13: =2*5.2 -> 10.4
A14: 10 | B14: SECI H-3 (Wind) | C14: AHEJ5L | D14: PPA | E14: =SUM(H14:S14) -> 202.8 | F14: =E14/5.2 -> 39 | G14: PSS-05 | N14: =15*5.2 -> 78 | O14: =9*5.2 -> 46.8 | P14: =4*5.2+7*5.2 -> 57.2 | S14: =4*5.2 -> 20.8
A15: 11a | B15: AGEL Merchant (Wind) | C15: AGE25CL | D15: Merchant | E15: =SUM(H15:S15) -> 156 | F15: =E15/5.2 -> 30 | G15: PSS-11 | Q15: =15*5.2 -> 78 | R15: =12*5.2 -> 62.4 | S15: =3*5.2 -> 15.6
A16: 12a | B16: AGEL Merchant (Wind) | C16: AGE26AL | D16: Merchant | E16: =SUM(H16:S16) -> 140.4 | F16: =E16/5.2 -> 27 | G16: PSS-12 | R16: =15*5.2 -> 78 | S16: =12*5.2 -> 62.4
B17: Total - MW | E17: =SUM(E5:E16) -> 1128.4 | H17: =SUM(H5:H16) -> 104 | I17: =SUM(I5:I16) -> 26 | J17: =SUM(J5:J16) -> 161.2 | K17: =SUM(K5:K16) -> 67.6 | L17: =SUM(L5:L16) -> 124.8 | M17: =SUM(M5:M16) -> 31.2 | N17: =SUM(N5:N16) -> 78 | O17: =SUM(O5:O16) -> 83.2 | ... S17: =SUM(S5:S16) -> 109.2
H18: =+SUM(H17:J17) -> 291.2 | K18: =+SUM(K17:M17) -> 223.6 | N18: =+SUM(N17:P17) -> 218.4 | Q18: =+SUM(Q17:S17) -> 395.2
B19: Total - WTG | F19: =SUM(F5:F16) -> 217 | H19: =+H17/5.2 -> 20 | I19: =+I17/5.2 -> 5 | J19: =+J17/5.2 -> 31 | K19: =+K17/5.2 -> 13 | L19: =+L17/5.2 -> 24 | M19: =+M17/5.2 -> 6 | N19: =+N17/5.2 -> 15 | O19: =+O17/5.2 -> 16 | ... S19: =+S17/5.2 -> 21
H20: =+SUM(H19:J19) -> 56 | K20: =+SUM(K19:M19) -> 43 | N20: =+SUM(N19:P19) -> 42 | Q20: =+SUM(Q19:S19) -> 76
A22: Additional for internal
A23: 11b | B23: AGEL Merchant (Wind) | C23: AGE25CL | D23: Merchant | E23: =SUM(H23:S23) -> 98.8 | F23: =E23/5.2 -> 19 | H23: =SUM(H24:H25) -> 0 | I23: =SUM(I24:I25) -> 0 | J23: =SUM(J24:J25) -> 0 | K23: =SUM(K24:K25) -> 0 | L23: =SUM(L24:L25) -> 0 | M23: =SUM(M24:M25) -> 0 | N23: =SUM(N24:N25) -> 0 | O23: =SUM(O24:O25) -> 0 | ... S23: =SUM(S24:S25) -> 72.8
E24: =SUM(H24:S24) -> 31.2 | F24: =E24/5.2 -> 6 | G24: PSS-11 | Q24: =2*5.2 -> 10.4 | R24: =3*5.2 -> 15.6 | S24: =1*5.2 -> 5.2
E25: =SUM(H25:S25) -> 67.6 | F25: =E25/5.2 -> 13 | G25: PSS-14 | S25: =13*5.2 -> 67.6
A26: 12b | B26: AGEL Merchant (Wind) | C26: AGE26AL | D26: Merchant | E26: =SUM(H26:S26) -> 312 | F26: =E26/5.2 -> 60 | G26: PSS-14 | Q26: =7*5.2 -> 36.4 | R26: =26*5.2 -> 135.2 | S26: =27*5.2 -> 140.4
A27: 13 | B27: AGEL Merchant | C27: AGE25BL | D27: Merchant | E27: =SUM(H27:S27) -> 10.4 | F27: =E27/5.2 -> 2 | G27: PSS-09 | Q27: =2*5.2 -> 10.4
B28: Total (for Internal) | E28: =SUM(E23:E27) -> 520 | F28: =SUM(F24:F27) -> 81 | H28: =SUM(H24:H27) -> 0 | I28: =SUM(I24:I27) -> 0 | J28: =SUM(J24:J27) -> 0 | K28: =SUM(K24:K27) -> 0 | L28: =SUM(L24:L27) -> 0 | M28: =SUM(M24:M27) -> 0 | N28: =SUM(N24:N27) -> 0 | O28: =SUM(O24:O27) -> 0 | ... S28: =SUM(S24:S27) -> 213.2
B30: Total - MW | E30: =+E28+E17 -> 1648.4 | F30: =+F28+F17 -> 81 | G30: =+G28+G17 -> 0 | H30: =+H28+H17 -> 104 | I30: =+I28+I17 -> 26 | J30: =+J28+J17 -> 161.2 | K30: =+K28+K17 -> 67.6 | L30: =+L28+L17 -> 124.8 | ... S30: =+S28+S17 -> 322.4
I32: Mwac | J32: WTG
H33: Budget Plan | I33: 1128 | J33: 217
H34: Internal Plan | I34: 1549.6 | J34: =I34/5.2 -> 298
H35: Actual YTD Dec-25 | I35: =J35*5.2 -> 733.2 | J35: 141
H36: Balance Budget | I36: =I33-I35 -> 394.8 | J36: =J33-J35 -> 76
H37: Balance Internal | I37: =I34-I35 -> 816.4 | J37: =J34-J35 -> 157

Sheet KH Solar Actual
A2: Phase-III: Khavda Solar Projects Monthly COD Actuals & Forecast (MWac) | Q2: TR Done in Nov-25 but COD in Dec-25 | Y2: 46021 | AB2: In addition to COD | AF2: Physical Progress Status till 27/28-Dec | AK2: Manpower as per DPR
A3: Priority | B3: Project | C3: SPV | D3: Plot No | E3: Category | F3: Category | G3: MMS Type | H3: Module Source | I3: Capacity (MWac) | J3: OL | K3: Capacity (MWdc) | L3: PSS No. | M3: PSS Charging Date | N3: SCOD | O3: 45748 | P3: 45778 | Q3: 45809 | R3: 45839 | S3: 45870 | T3: 45901 | U3: 45931 | V3: 45962 | W3: 45992 | X3: 46023 | Y3: 46054 | Z3: 46082 | AB3: Charging | AC3: Trail Run | AD3: Trail Run Certificate | AF3: Piling | AG3: MMS (Purlin) | AH3: Module | AI3: IDT | AK3: Avaliable as of 27/28-Dec | AL3: Required
A4: A. Khavda Solar Projects
A5: 1 | B5: AGEL Merchant | C5: ARE56L | D5: S-08 | E5: Merchant | F5: Merchant | G5: HSAT | H5: ALMM | I5: 250 | J5: 1.37 | K5: =I5*J5 -> 342.5 | L5: PSS-09 | M5: 45612 | P5: 75 | Q5: 50 | S5: 125 | T5: 0 | AB5: 0 | AC5: 0 | AD5: 0 | AF5: Completed | AG5: Completed | AH5: Completed | AI5: Completed
A6: 2 | B6: AGEL Merchant | C6: ARE56L | D6: A-02 | E6: Merchant | F6: Merchant | G6: HSAT | H6: ALMM | I6: 50 | J6: 1.37 | K6: =I6*J6 -> 68.5 | L6: PSS-04 | M6: 45714 | P6: 50 | Q6: 0 | R6: 0 | S6: 0 | T6: 0 | AB6: 0 | AC6: 0 | AD6: 0 | AF6: Completed | AG6: Completed | AH6: Completed | AI6: Completed
A7: 3 | B7: MLP AP New | C7: ARE57L | D7: A-11 | E7: PPA | F7: PPA | G7: HSAT | H7: China | I7: 187.5 | J7: 1.36 | K7: =I7*J7 -> 255 | L7: PSS-13 | M7: 45708 | N7: 15-Jun-29 (LTA +15D) | O7: 75 | P7: 112.5 | Q7: 0 | R7: 0 | S7: 0 | T7: 0 | AB7: 0 | AC7: 0 | AD7: 0 | AF7: Completed | AG7: Completed | AH7: Completed | AI7: Completed
A8: 4 | B8: MLP AP New | C8: ARE57L | D8: A-12 | E8: PPA | F8: PPA | G8: HSAT | H8: China | I8: 350 | J8: 1.35 | K8: =I8*J8 -> 472.5 | L8: PSS-13 | M8: 45708 | N8: 15-Jun-29 (LTA +15D) | P8: 50 | Q8: 175 | V8: 125 | AF8: Completed | AG8: Completed | AH8: Completed | AI8: Completed | AK8: 0 | AL8: =+AK8 -> 0
A9: 5 | B9: SECI H-3 | C9: AHEJ5L | D9: A-13 | E9: PPA | F9: PPA | G9: FT | H9: China | I9: 570 | J9: 1.4 | K9: =I9*J9 -> 798 | L9: PSS-05 | M9: 45721 | N9: 31-Dec-25 (LTA) | O9: 145 | Q9: 150 | S9: 50 | T9: 75 | U9: 75 | W9: 75 | AF9: Completed | AG9: Completed | AH9: Completed | AI9: Completed | AK9: 7 | AL9: =+AK9 -> 7
A10: 6 | B10: AGEL Merchant | C10: ARE45L | D10: A-14 | E10: Merchant | F10: Merchant | G10: HSAT | H10: ALMM | I10: 250 | J10: 1.37 | K10: =I10*J10 -> 342.5 | L10: PSS-05 | M10: 45721 | O10: 50 | Q10: 125 | T10: 75 | U10: 0 | AF10: Completed | AG10: Completed | AH10: Completed | AI10: Completed
A11: 7 | B11: MLP T3 AP | C11: ARE56L | D11: S-06 | E11: PPA | F11: PPA | G11: HSAT | H11: China | I11: 500 | J11: 1.37 | K11: =I11*J11 -> 685 | L11: PSS-10 | M11: 45741 | N11: 45990 | O11: 100 | Q11: 137.5 | S11: 87.5 | T11: 100 | V11: 75 | AF11: Completed | AG11: Completed | AH11: Completed | AI11: Completed | AK11: 0 | AL11: =+AK11 -> 0
A12: P-01 | B12: Google Hybrid | C12: ARE3L | D12: A-6 | E12: Merchant-Google | F12: Merchant | G12: HSAT | H12: ALMM | I12: 25 | J12: 1.35 | K12: =J12*I12 -> 33.75 | L12: PSS-08 | M12: 45851 | N12: - | R12: 25 | S12: 0 | T12: 0 | U12: 0 | W12: 0 | AF12: Completed | AG12: Completed | AH12: Completed | AI12: Completed
A13: P-02 | B13: AGEL Merchant | C13: ASEJ6PL | D13: A-6 | E13: Merchant-Hybrid | F13: Merchant | G13: HSAT | H13: ALMM | I13: 35 | J13: 1.35 | K13: =J13*I13 -> 47.25 | L13: PSS-08 | M13: 45851 | N13: - | R13: 35 | S13: 0 | T13: 0 | U13: 0 | W13: 0 | AF13: Completed | AG13: Completed | AH13: Completed | AI13: Completed
A14: P-03 | B14: AGEL Hybrid Merchant | C14: AGE25BL | D14: S-8 | E14: Merchant-Hybrid | F14: Merchant | G14: HSAT | H14: ALMM | I14: 100 | J14: 1.35 | K14: =J14*I14 -> 135 | L14: PSS-09 | M14: 45612 | N14: - | T14: 100 | AF14: Completed | AG14: Completed | AH14: Completed | AI14: Completed
A15: P-04 | B15: AGEL Merchant | C15: AHEJ5L | D15: A-15a | E15: Merchant | F15: Merchant | G15: HSAT | H15: ALMM | I15: 150 | J15: 1.35 | K15: =J15*I15 -> 202.5 | L15: PSS-08 | M15: 45851 | N15: - | T15: 50 | X15: 50 | Y15: 50 | AF15: 0.97 | AG15: 0.817 | AH15: 0.62 | AI15: C:92%; E:83% | AK15: 360 | AL15: 240
A16: P-05 | B16: AGEL Hybrid Merchant | C16: AGE26BL | D16: S-5 | E16: Merchant-Hybrid | F16: Merchant | G16: HSAT | H16: ALMM | I16: =SUM(I17:I18) -> 292 | J16: 1.35 | K16: =J16*I16 -> 394.2 | L16: PSS-10 | M16: 45876 | N16: - | O16: =SUM(O17:O18) -> 0 | P16: =SUM(P17:P18) -> 0 | Q16: =SUM(Q17:Q18) -> 0 | R16: =SUM(R17:R18) -> 0 | S16: =SUM(S17:S18) -> 0 | T16: =SUM(T17:T18) -> 50 | U16: =SUM(U17:U18) -> 0 | V16: =SUM(V17:V18) -> 50 | ... AA16: =SUM(AA17:AA18) -> 0 | AD16: =SUM(AD17:AD18) -> 0 | AF16: 0.994 | AG16: 0.896 | AH16: 0.584 | AI16: C:100%; E:83% | AK16: 358 | AL16: 480
A17: P-05a | B17: AGEL Hybrid Merchant | C17: AGE26BL | D17: S-5 | E17: Merchant-Hybrid | F17: Merchant | G17: HSAT | H17: ALMM | I17: 142 | J17: 1.35 | K17: =J17*I17 -> 191.7 | M17: 45876 | N17: - | T17: 50 | V17: 50 | Y17: 42
A18: P-05b | B18: AGEL Merchant | C18: AGE26BL | D18: S-5 | E18: Merchant-Hybrid | F18: Merchant | G18: HSAT | H18: ALMM | I18: 150 | J18: 1.35 | K18: =J18*I18 -> 202.5 | M18: 45876 | N18: - | W18: 50 | X18: 75 | Y18: 25
A19: P-06 | B19: AGEL Merchant | C19: AGE24L | D19: S-5 | E19: Merchant | F19: Merchant | G19: HSAT | H19: ALMM | I19: 150 | J19: 1.35 | K19: =J19*I19 -> 202.5 | L19: PSS-10 | M19: 45876 | N19: - | X19: 62.5 | Y19: 87.5 | AF19: 0.98 | AG19: 0.817 | AH19: 0.46433553 | AI19: C:100%; E:83% | AK19: 520 | AL19: 380
A20: P-07 | B20: AGEL Merchant | C20: AGE24L | D20: A-14 | E20: Merchant | F20: Merchant | G20: HSAT | H20: ALMM | I20: 150 | J20: 1.35 | K20: =J20*I20 -> 202.5 | L20: PSS-05 | M20: 45721 | N20: - | X20: 75 | Y20: 75 | AF20: 0.95 | AG20: 0.487 | AH20: 0.133 | AI20: C:50%; E:50% | AK20: 412 | AL20: 840
A21: P-08 | B21: Cement - Hybrid | C21: ACL | D21: A-1 | E21: Cement - Hybrid | F21: Group | G21: FT | H21: ALMM | I21: 125 | J21: 1.36 | K21: =J21*I21 -> 170 | L21: PSS-04 | M21: 45714 | N21: - | T21: 50 | W21: 75 | AF21: Completed | AG21: Completed | AH21: Completed | AI21: Completed
A22: P-09 | B22: MLP T3 AP | C22: AGE25CL | D22: A-6 | E22: PPA | F22: PPA | G22: HSAT | H22: China | I22: 75 | J22: 1.35 | K22: =J22*I22 -> 101.25 | L22: PSS-08 | M22: 45851 | N22: 45990 | W22: 75 | Z22: 0 | AF22: Completed | AG22: Completed | AH22: Completed | AI22: Completed
A23: P-10 | B23: MLP T1 J&K | C23: AGE26AL | D23: A-16a | E23: PPA | F23: PPA | G23: FT | H23: SEA | I23: 50 | J23: 1.3306 | K23: =J23*I23 -> 66.53 | L23: PSS-06 | M23: 45997 | N23: 46034 | X23: 50 | AF23: Completed | AG23: Completed | AH23: Completed | AI23: Completed | AK23: 129 | AL23: 250
A24: P-11 | B24: MLP T1 CG | C24: AGE26AL | D24: A-16b | E24: PPA | F24: PPA | G24: FT | H24: SEA | I24: 200 | J24: 1.3181 | K24: =J24*I24 -> 263.62 | L24: PSS-06 | M24: 45997 | N24: 46034 | X24: 175 | Y24: 25 | AF24: 0.77 | AG24: 0.417 | AH24: 0.278 | AI24: C:63%; E:63% | AK24: 659 | AL24: 1050
A25: P-12 | B25: MLP T1 TN | C25: AGE26AL | D25: A-16c | E25: PPA | F25: PPA | G25: FT | H25: SEA | I25: 167 | J25: 1.3293413 | K25: =J25*I25 -> 222 | L25: PSS-06 | M25: 45997 | N25: 46034 | X25: 100 | Y25: 67 | AF25: 0.6093 | AG25: 0.019262855 | AI25: C:0%; E:0% | AK25: 331 | AL25: 1020
A26: P-13 | B26: MLP T1 OR | C26: AGE26AL | D26: A-16d | E26: PPA | F26: PPA | G26: FT | H26: SEA | I26: 333 | J26: 1.3243243 | K26: =J26*I26 -> 441 | L26: PSS-06 | M26: 46049 | N26: 46034 | X26: 150 | Y26: 183 | AB26: 0 | AC26: 0 | AD26: 0 | AF26: 0.5239 | AG26: 0.03 | AI26: C:15%; E:11% | AK26: 304 | AL26: 1620
A27: P-14 | B27: MLP T1 TR | C27: AGE26AL | D27: A10a | E27: PPA | F27: PPA | G27: FT | H27: SEA | I27: 50 | J27: 1.36 | K27: =J27*I27 -> 68 | L27: PSS-03 | M27: 45373 | N27: 08-Dec-25 (LTA -23D) | U27: 50 | AB27: 0 | AC27: 0 | AF27: 0.9952 | AG27: 0.962 | AH27: 0.91 | AI27: Completed | AK27: 56 | AL27: 90
A28: P-15 | B28: MLP T3 AP | C28: AGE25CL | D28: A-6 | E28: PPA | F28: PPA | G28: FT | H28: China | I28: 425 | J28: 1.36 | K28: =J28*I28 -> 578 | L28: PSS-08 | M28: 45961 | N28: 45990 | X28: 100 | Y28: 150 | Z28: 175 | AB28: 0 | AC28: 0 | AD28: 0 | AF28: 0.678 | AG28: 0.1813 | AI28: C:59%; E:47% | AK28: 794 | AL28: 1420
